[2025-07-08T11:41:52.201+0000] {local_task_job_runner.py:123} INFO - ::group::Pre task execution logs
[2025-07-08T11:41:52.208+0000] {taskinstance.py:2612} INFO - Dependencies all met for dep_context=non-requeueable deps ti=<TaskInstance: extract_raw_data_pipeline.run_dbt_staging manual__2025-07-08T11:41:45.934826+00:00 [queued]>
[2025-07-08T11:41:52.212+0000] {taskinstance.py:2612} INFO - Dependencies all met for dep_context=requeueable deps ti=<TaskInstance: extract_raw_data_pipeline.run_dbt_staging manual__2025-07-08T11:41:45.934826+00:00 [queued]>
[2025-07-08T11:41:52.212+0000] {taskinstance.py:2865} INFO - Starting attempt 1 of 1
[2025-07-08T11:41:52.218+0000] {taskinstance.py:2888} INFO - Executing <Task(BashOperator): run_dbt_staging> on 2025-07-08 11:41:45.934826+00:00
[2025-07-08T11:41:52.220+0000] {standard_task_runner.py:72} INFO - Started process 246 to run task
[2025-07-08T11:41:52.223+0000] {standard_task_runner.py:104} INFO - Running: ['***', 'tasks', 'run', 'extract_raw_data_pipeline', 'run_dbt_staging', 'manual__2025-07-08T11:41:45.934826+00:00', '--job-id', '42', '--raw', '--subdir', 'DAGS_FOLDER/driven_data_pipeline.py', '--cfg-path', '/tmp/tmpfikzfw1j']
[2025-07-08T11:41:52.223+0000] {standard_task_runner.py:105} INFO - Job 42: Subtask run_dbt_staging
[2025-07-08T11:41:52.246+0000] {task_command.py:467} INFO - Running <TaskInstance: extract_raw_data_pipeline.run_dbt_staging manual__2025-07-08T11:41:45.934826+00:00 [running]> on host c95656197d4a
[2025-07-08T11:41:52.280+0000] {taskinstance.py:3131} INFO - Exporting env vars: AIRFLOW_CTX_DAG_OWNER='***' AIRFLOW_CTX_DAG_ID='extract_raw_data_pipeline' AIRFLOW_CTX_TASK_ID='run_dbt_staging' AIRFLOW_CTX_EXECUTION_DATE='2025-07-08T11:41:45.934826+00:00' AIRFLOW_CTX_TRY_NUMBER='1' AIRFLOW_CTX_DAG_RUN_ID='manual__2025-07-08T11:41:45.934826+00:00'
[2025-07-08T11:41:52.281+0000] {logging_mixin.py:190} INFO - Task instance is in running state
[2025-07-08T11:41:52.282+0000] {logging_mixin.py:190} INFO -  Previous state of the Task instance: queued
[2025-07-08T11:41:52.282+0000] {logging_mixin.py:190} INFO - Current task name:run_dbt_staging state:running start_date:2025-07-08 11:41:52.209388+00:00
[2025-07-08T11:41:52.282+0000] {logging_mixin.py:190} INFO - Dag name:extract_raw_data_pipeline and current dag run status:running
[2025-07-08T11:41:52.282+0000] {taskinstance.py:731} INFO - ::endgroup::
[2025-07-08T11:41:52.282+0000] {subprocess.py:63} INFO - Tmp dir root location: /tmp
[2025-07-08T11:41:52.284+0000] {subprocess.py:75} INFO - Running command: ['/usr/bin/bash', '-c', 'set -x; cd /opt/***/dbt && dbt run --select tag:staging']
[2025-07-08T11:41:52.289+0000] {subprocess.py:86} INFO - Output:
[2025-07-08T11:41:52.291+0000] {subprocess.py:93} INFO - + cd /opt/***/dbt
[2025-07-08T11:41:52.291+0000] {subprocess.py:93} INFO - + dbt run --select tag:staging
[2025-07-08T11:41:53.539+0000] {subprocess.py:93} INFO - [0m11:41:53  Running with dbt=1.8.0
[2025-07-08T11:41:53.658+0000] {subprocess.py:93} INFO - [0m11:41:53  Registered adapter: postgres=1.8.2
[2025-07-08T11:41:53.747+0000] {subprocess.py:93} INFO - [0m11:41:53  Unable to do partial parsing because of a version mismatch
[2025-07-08T11:41:54.340+0000] {subprocess.py:93} INFO - [0m11:41:54  Found 9 models, 10 sources, 428 macros
[2025-07-08T11:41:54.342+0000] {subprocess.py:93} INFO - [0m11:41:54
[2025-07-08T11:41:54.374+0000] {subprocess.py:93} INFO - [0m11:41:54
[2025-07-08T11:41:54.374+0000] {subprocess.py:93} INFO - [0m11:41:54  Finished running  in 0 hours 0 minutes and 0.03 seconds (0.03s).
[2025-07-08T11:41:54.375+0000] {subprocess.py:93} INFO - [0m11:41:54  Encountered an error:
[2025-07-08T11:41:54.375+0000] {subprocess.py:93} INFO - Database Error
[2025-07-08T11:41:54.375+0000] {subprocess.py:93} INFO -   connection to server at "localhost" (::1), port 5432 failed: Connection refused
[2025-07-08T11:41:54.375+0000] {subprocess.py:93} INFO -   	Is the server running on that host and accepting TCP/IP connections?
[2025-07-08T11:41:54.375+0000] {subprocess.py:93} INFO -   connection to server at "localhost" (127.0.0.1), port 5432 failed: Connection refused
[2025-07-08T11:41:54.375+0000] {subprocess.py:93} INFO -   	Is the server running on that host and accepting TCP/IP connections?
[2025-07-08T11:41:54.375+0000] {subprocess.py:93} INFO - 
[2025-07-08T11:41:55.205+0000] {subprocess.py:97} INFO - Command exited with return code 2
[2025-07-08T11:41:55.215+0000] {taskinstance.py:3310} ERROR - Task failed with exception
Traceback (most recent call last):
  File "/home/airflow/.local/lib/python3.10/site-packages/airflow/models/taskinstance.py", line 767, in _execute_task
    result = _execute_callable(context=context, **execute_callable_kwargs)
  File "/home/airflow/.local/lib/python3.10/site-packages/airflow/models/taskinstance.py", line 733, in _execute_callable
    return ExecutionCallableRunner(
  File "/home/airflow/.local/lib/python3.10/site-packages/airflow/utils/operator_helpers.py", line 252, in run
    return self.func(*args, **kwargs)
  File "/home/airflow/.local/lib/python3.10/site-packages/airflow/models/baseoperator.py", line 406, in wrapper
    return func(self, *args, **kwargs)
  File "/home/airflow/.local/lib/python3.10/site-packages/airflow/operators/bash.py", line 249, in execute
    raise AirflowException(
airflow.exceptions.AirflowException: Bash command failed. The command returned a non-zero exit code 2.
[2025-07-08T11:41:55.217+0000] {logging_mixin.py:190} INFO - Task instance in failure state
[2025-07-08T11:41:55.218+0000] {logging_mixin.py:190} INFO - Task start:2025-07-08 11:41:52.209388+00:00 end:2025-07-08 11:41:55.217428+00:00 duration:3.00804
[2025-07-08T11:41:55.218+0000] {logging_mixin.py:190} INFO - Task:<Task(BashOperator): run_dbt_staging> dag:<DAG: extract_raw_data_pipeline> dagrun:<DagRun extract_raw_data_pipeline @ 2025-07-08 11:41:45.934826+00:00: manual__2025-07-08T11:41:45.934826+00:00, state:running, queued_at: 2025-07-08 11:41:45.964631+00:00. externally triggered: True>
[2025-07-08T11:41:55.218+0000] {logging_mixin.py:190} INFO - Failure caused by Bash command failed. The command returned a non-zero exit code 2.
[2025-07-08T11:41:55.218+0000] {taskinstance.py:1225} INFO - Marking task as FAILED. dag_id=extract_raw_data_pipeline, task_id=run_dbt_staging, run_id=manual__2025-07-08T11:41:45.934826+00:00, execution_date=20250708T114145, start_date=20250708T114152, end_date=20250708T114155
[2025-07-08T11:41:55.225+0000] {taskinstance.py:340} INFO - ::group::Post task execution logs
[2025-07-08T11:41:55.225+0000] {standard_task_runner.py:124} ERROR - Failed to execute job 42 for task run_dbt_staging (Bash command failed. The command returned a non-zero exit code 2.; 246)
Traceback (most recent call last):
  File "/home/airflow/.local/lib/python3.10/site-packages/airflow/task/task_runner/standard_task_runner.py", line 117, in _start_by_fork
    ret = args.func(args, dag=self.dag)
  File "/home/airflow/.local/lib/python3.10/site-packages/airflow/cli/cli_config.py", line 49, in command
    return func(*args, **kwargs)
  File "/home/airflow/.local/lib/python3.10/site-packages/airflow/utils/cli.py", line 115, in wrapper
    return f(*args, **kwargs)
  File "/home/airflow/.local/lib/python3.10/site-packages/airflow/cli/commands/task_command.py", line 483, in task_run
    task_return_code = _run_task_by_selected_method(args, _dag, ti)
  File "/home/airflow/.local/lib/python3.10/site-packages/airflow/cli/commands/task_command.py", line 256, in _run_task_by_selected_method
    return _run_raw_task(args, ti)
  File "/home/airflow/.local/lib/python3.10/site-packages/airflow/cli/commands/task_command.py", line 341, in _run_raw_task
    return ti._run_raw_task(
  File "/home/airflow/.local/lib/python3.10/site-packages/airflow/utils/session.py", line 97, in wrapper
    return func(*args, session=session, **kwargs)
  File "/home/airflow/.local/lib/python3.10/site-packages/airflow/models/taskinstance.py", line 3004, in _run_raw_task
    return _run_raw_task(
  File "/home/airflow/.local/lib/python3.10/site-packages/airflow/models/taskinstance.py", line 273, in _run_raw_task
    TaskInstance._execute_task_with_callbacks(
  File "/home/airflow/.local/lib/python3.10/site-packages/airflow/models/taskinstance.py", line 3158, in _execute_task_with_callbacks
    result = self._execute_task(context, task_orig)
  File "/home/airflow/.local/lib/python3.10/site-packages/airflow/models/taskinstance.py", line 3182, in _execute_task
    return _execute_task(self, context, task_orig)
  File "/home/airflow/.local/lib/python3.10/site-packages/airflow/models/taskinstance.py", line 767, in _execute_task
    result = _execute_callable(context=context, **execute_callable_kwargs)
  File "/home/airflow/.local/lib/python3.10/site-packages/airflow/models/taskinstance.py", line 733, in _execute_callable
    return ExecutionCallableRunner(
  File "/home/airflow/.local/lib/python3.10/site-packages/airflow/utils/operator_helpers.py", line 252, in run
    return self.func(*args, **kwargs)
  File "/home/airflow/.local/lib/python3.10/site-packages/airflow/models/baseoperator.py", line 406, in wrapper
    return func(self, *args, **kwargs)
  File "/home/airflow/.local/lib/python3.10/site-packages/airflow/operators/bash.py", line 249, in execute
    raise AirflowException(
airflow.exceptions.AirflowException: Bash command failed. The command returned a non-zero exit code 2.
[2025-07-08T11:41:55.234+0000] {local_task_job_runner.py:266} INFO - Task exited with return code 1
[2025-07-08T11:41:55.251+0000] {taskinstance.py:3900} INFO - 0 downstream tasks scheduled from follow-on schedule check
[2025-07-08T11:41:55.253+0000] {local_task_job_runner.py:245} INFO - ::endgroup::
